Workbook
Name BOOL_VALUES: 'Constant List'!$H$2:$H$3
Name GEN_TYPES: 'Constant List'!$A$2:$A$7
Name OUTPUT_TYPES_BOOLEAN: 'Constant List'!$R$2:$R$4
Name OUTPUT_TYPES_DATE: 'Constant List'!$P$2:$P$5
Name OUTPUT_TYPES_FLOAT: 'Constant List'!$O$2:$O$4
Name OUTPUT_TYPES_INT: 'Constant List'!$N$2:$N$5
Name OUTPUT_TYPES_STRING: 'Constant List'!$M$2:$M$3
Name OUTPUT_TYPES_TIMESTAMP: 'Constant List'!$Q$2:$Q$5

Sheet Инструкция
A1: Шаблон DataGen: как заполнять Excel
A3: Шаг 1 | B3: На листе tables заполните schema_name, table_name и total_rows.
A4: Шаг 2 | B4: Для каждой строки из tables используйте отдельный лист с именем schema.table.
A5: Шаг 3 | B5: В листе таблицы обязательны column_name и gen_data_type; output_data_type можно оставить пустым.
A6: Шаг 4 | B6: constraints заполняется одной строкой в формате key=value; key=value.
A7: Шаг 5 | B7: allowed_values всегда задается JSON-массивом: ["A", "B"], [1, 2], [true, false].
A8: Шаг 6 | B8: foreign_key тоже задается одной строкой key=value; key=value.
A9: Шаг 7 | B9: Для foreign_key допустим только null_ratio; остальные generator constraints запрещены.
A10: Шаг 8 | B10: Для primary key обязателен null_ratio=0.
A11: Шаг 9 | B11: output_data_type выбирается только из допустимого dropdown по выбранному gen_data_type.
A13: Общие колонки
A14: column_name | B14: Имя итоговой колонки в таблице.
A15: gen_data_type | B15: Исходный тип генератора: STRING, INT, FLOAT, DATE, TIMESTAMP, BOOLEAN.
A16: output_data_type | B16: Финальный тип после конвертации; если пусто, результат остается в gen_data_type.
A17: is_primary_key | B17: TRUE если колонка первичный ключ; тогда значение должно быть уникальным и null_ratio обязан быть 0.
A18: constraints | B18: Одна строка key=value; key=value с ограничениями для выбранного gen_data_type.
A19: foreign_key | B19: Одна строка key=value; key=value со ссылкой на родительскую колонку.
A21: Общие constraints
A22: null_ratio | B22: Доля NULL в итоговых данных от 0 до 1.
A23: is_unique | B23: Требует уникальные итоговые значения после всех конвертаций.
A24: allowed_values | B24: Ограничивает генерацию только указанным списком значений; задается только JSON-массивом.
A26: STRING constraints
A27: length | B27: Фиксированная длина строки.
A28: character_set | B28: Набор символов: letters = только буквы, digits = только цифры, alphanumeric = буквы и цифры.
A29: case_mode | B29: Регистр строки: mixed = смешанный регистр, lower = только нижний регистр, upper = только верхний регистр.
A30: regular_expr | B30: Regex-шаблон, которому должна соответствовать строка.
A32: INT / FLOAT constraints
A33: min_value | B33: Минимальное числовое значение для INT или FLOAT.
A34: max_value | B34: Максимальное числовое значение для INT или FLOAT.
A35: precision | B35: Количество знаков после запятой; используется только для FLOAT.
A37: DATE constraints
A38: min_value | B38: Минимальная дата; задается строкой, которую можно распарсить как дату.
A39: max_value | B39: Максимальная дата; задается строкой, которую можно распарсить как дату.
A40: date_format | B40: Формат текстового вывода даты, например %Y-%m-%d; обычно используется вместе с output_data_type=STRING.
A42: TIMESTAMP constraints
A43: min_timestamp | B43: Минимальный timestamp в формате строки, например 2024-01-01 00:00:00.
A44: max_timestamp | B44: Максимальный timestamp в формате строки, например 2024-12-31 23:59:59.
A45: timestamp_format | B45: Формат текстового вывода timestamp, например %Y-%m-%d %H:%M:%S.
A47: BOOLEAN constraints
A48: allowed_values | B48: Обычно [true, false], но можно ограничить, например, только [true].
...

Sheet Constant List
A1: Data Type | B1: Constraint Hint | H1: Bool | J1: Foreign Key Example | M1: OUTPUT_TYPES_STRING | N1: OUTPUT_TYPES_INT | O1: OUTPUT_TYPES_FLOAT | P1: OUTPUT_TYPES_DATE | Q1: OUTPUT_TYPES_TIMESTAMP | R1: OUTPUT_TYPES_BOOLEAN
A2: STRING | B2: Формат constraints: null_ratio=0..1; is_unique=true/false; allowed_values=["A", "B"]; length=10; character_set="letters|digits|alphanumeric"; case_mode="mixed|lower|upper"; regular_expr="^[A-Z0-9]{6}$" | H2: TRUE | J2: schema_name="analytics_db"; table_name="company_groups"; column_name="INN"; relation_type="ONE_TO_MANY|ONE_TO_ONE" | M2: STRING | N2: INT | O2: FLOAT | P2: DATE | Q2: TIMESTAMP | R2: BOOLEAN
A3: INT | B3: Формат constraints: null_ratio=0..1; is_unique=true/false; allowed_values=[1, 2, 3]; min_value=0; max_value=1000 | H3: FALSE | M3: INT | N3: FLOAT | O3: STRING | P3: STRING | Q3: STRING | R3: STRING
A4: FLOAT | B4: Формат constraints: null_ratio=0..1; is_unique=true/false; allowed_values=[10.5, 20.25]; min_value=0.0; max_value=1000.0; precision=2 | N4: STRING | O4: INT | P4: INT | Q4: INT | R4: INT
A5: DATE | B5: Формат constraints: null_ratio=0..1; is_unique=true/false; allowed_values=["2024-01-01", "2024-01-02"]; min_value="2024-01-01"; max_value="2024-12-31"; date_format="%Y-%m-%d" | N5: BOOLEAN | P5: TIMESTAMP | Q5: DATE
A6: TIMESTAMP | B6: Формат constraints: null_ratio=0..1; is_unique=true/false; allowed_values=["2024-01-01 00:00:00", "2024-01-01 00:01:00"]; min_timestamp="2024-01-01 00:00:00"; max_timestamp="2024-12-31 23:59:59"; timestamp_format="%Y-%m-%d %H:%M:%S"
A7: BOOLEAN | B7: Формат constraints: null_ratio=0..1; is_unique=true/false; allowed_values=[true, false]

Sheet tables
A1: source_type | B1: source_name
A2: json | B2: example_source
A6: schema_name | B6: table_name | C6: total_rows
A7: analytics_db | B7: company_groups | C7: 5000
A8: analytics_db | B8: subjects | C8: 10000

Sheet analytics_db.company_groups
A1: column_name | B1: gen_data_type | C1: output_data_type | D1: is_primary_key | E1: constraints | F1: foreign_key | G1: Подсказка по constraints | H1: Пример заполнения foreign_key
A2: INN | B2: STRING | C2: INT | D2: TRUE | E2: null_ratio=0; is_unique=true; length=10; character_set="digits" | G2: =IF($F2<>"","Для foreign_key допустим только null_ratio=0..1. Остальные generator constraints запрещены.",IFERROR(VLOOKUP($B2,'Constant List'!$A$2:$B$7,2,FALSE),"Тип данных не заполнен")) | H2: ='Constant List'!$J$2
A3: GROUP_ID_DM | B3: INT | E3: null_ratio=0; min_value=1; max_value=6000000 | G3: =IF($F3<>"","Для foreign_key допустим только null_ratio=0..1. Остальные generator constraints запрещены.",IFERROR(VLOOKUP($B3,'Constant List'!$A$2:$B$7,2,FALSE),"Тип данных не заполнен")) | H3: ='Constant List'!$J$2
A4: MAIN_COMPANY_FLG_DM | B4: INT | E4: allowed_values=[0, 1] | G4: =IF($F4<>"","Для foreign_key допустим только null_ratio=0..1. Остальные generator constraints запрещены.",IFERROR(VLOOKUP($B4,'Constant List'!$A$2:$B$7,2,FALSE),"Тип данных не заполнен")) | H4: ='Constant List'!$J$2
A5: VALUE_DAY | B5: DATE | C5: INT | E5: date_format="%Y%m%d" | G5: =IF($F5<>"","Для foreign_key допустим только null_ratio=0..1. Остальные generator constraints запрещены.",IFERROR(VLOOKUP($B5,'Constant List'!$A$2:$B$7,2,FALSE),"Тип данных не заполнен")) | H5: ='Constant List'!$J$2

Sheet analytics_db.subjects
A1: column_name | B1: gen_data_type | C1: output_data_type | D1: is_primary_key | E1: constraints | F1: foreign_key | G1: Подсказка по constraints | H1: Пример заполнения foreign_key
A2: STYPE | B2: STRING | E2: allowed_values=["c", "cpr"] | G2: =IF($F2<>"","Для foreign_key допустим только null_ratio=0..1. Остальные generator constraints запрещены.",IFERROR(VLOOKUP($B2,'Constant List'!$A$2:$B$7,2,FALSE),"Тип данных не заполнен")) | H2: ='Constant List'!$J$2
A3: SINN | B3: INT | F3: schema_name="analytics_db"; table_name="company_groups"; column_name="INN"; relation_type="ONE_TO_MANY" | G3: =IF($F3<>"","Для foreign_key допустим только null_ratio=0..1. Остальные generator constraints запрещены.",IFERROR(VLOOKUP($B3,'Constant List'!$A$2:$B$7,2,FALSE),"Тип данных не заполнен")) | H3: ='Constant List'!$J$2
A4: SOGRN | B4: INT | E4: null_ratio=0.1; min_value=1000000000000; max_value=1000000000000000 | G4: =IF($F4<>"","Для foreign_key допустим только null_ratio=0..1. Остальные generator constraints запрещены.",IFERROR(VLOOKUP($B4,'Constant List'!$A$2:$B$7,2,FALSE),"Тип данных не заполнен")) | H4: ='Constant List'!$J$2
A5: SPIN | B5: STRING | E5: null_ratio=0.1; length=6; case_mode="upper"; regular_expr="^[A-Z0-9]{6}$" | G5: =IF($F5<>"","Для foreign_key допустим только null_ratio=0..1. Остальные generator constraints запрещены.",IFERROR(VLOOKUP($B5,'Constant List'!$A$2:$B$7,2,FALSE),"Тип данных не заполнен")) | H5: ='Constant List'!$J$2
A6: SABSCODE | B6: STRING | E6: allowed_values=["SFAProd"] | G6: =IF($F6<>"","Для foreign_key допустим только null_ratio=0..1. Остальные generator constraints запрещены.",IFERROR(VLOOKUP($B6,'Constant List'!$A$2:$B$7,2,FALSE),"Тип данных не заполнен")) | H6: ='Constant List'!$J$2
A7: SPINSFA | B7: STRING | E7: regular_expr="^ABR-FW-SCRMFW-WORK-ACCOUNT ACB-\d+$" | G7: =IF($F7<>"","Для foreign_key допустим только null_ratio=0..1. Остальные generator constraints запрещены.",IFERROR(VLOOKUP($B7,'Constant List'!$A$2:$B$7,2,FALSE),"Тип данных не заполнен")) | H7: ='Constant List'!$J$2
A8: IDSUBJECT | B8: INT | E8: min_value=1; max_value=20000000 | G8: =IF($F8<>"","Для foreign_key допустим только null_ratio=0..1. Остальные generator constraints запрещены.",IFERROR(VLOOKUP($B8,'Constant List'!$A$2:$B$7,2,FALSE),"Тип данных не заполнен")) | H8: ='Constant List'!$J$2
